Workbook
Name ALUM: Gen_form!$P$465:$P$466
Name ALUM_0: Gen_form!$M$465
Name ALUM_1: Gen_form!$M$466
Name ALUM_2: Gen_form!$M$467
Name ALUM_3: Gen_form!$M$468
Name ALUM_4: Gen_form!$M$469
Name ALUM_5: Gen_form!$M$470
Name ALUMHIGH: Gen_form!$P$466
Name ALUMLOW: Gen_form!$P$465
Name avgkvp: Gen_form!$Q$465
Name COMPG1: Gen_form!$B$133:$K$198
Name COMPG2: Gen_form!$B$199:$K$264
Name CTPG1: Gen_form!$B$727:$K$792
Name DHALF: Gen_form!$O$465:$O$470
Name EXP_0: Gen_form!$N$465
Name EXP_1: Gen_form!$N$466
Name EXP_2: Gen_form!$N$467
Name EXP_3: Gen_form!$N$468
Name EXP_4: Gen_form!$N$469
Name EXP_5: Gen_form!$N$470
Name EXP_BLD: Gen_form!$B$265:$K$330
Name EXPHIGH: Gen_form!$P$470
Name EXPLOW: Gen_form!$P$469
Name FIRST: Gen_form!$B$1:$K$132
Name FS_KV: Gen_form!$B$331:$K$396
Name HVL: Gen_form!$S$465
Name HVL_IMGQUAL: Gen_form!$B$595:$K$660
Name LFMAS: Gen_form!$P$207
Name LFSDD: Gen_form!$N$233
Name LIN: Gen_form!$B$529:$K$594
Name LN_EXP: Gen_form!$Q$469:$Q$470
Name MAXAVG: Gen_form!$U$444
Name OUTPUT: Gen_form!$B$661:$K$726
Name RadSafe: Gen_form!$M$514
Name REPRO: Gen_form!$B$397:$K$462
Name SFMAS: Gen_form!$P$212
Name SFSDD: Gen_form!$N$251
Name startend: Gen_form!$O$8
Name TBCM_IN: Gen_form!$V$182
Name TIM: Gen_form!$B$463:$K$528
Name TO10Group: Tables!$O$92:$O$104
Name TO10kVAdj: Tables!$I$92:$M$106
Name TO10Values: Tables!$A$113:$S$125
Name TO16Group: Tables!$A$127:$A$139
Name TO16Values: Tables!$A$127:$O$139

Sheet Gen_form
A1: 1 | M1: Revision 0.2-20260319 (Has 39 data records) | T1: =IF(OR(AB246="",AB246=0),"",AB246) | Y1: PRINT AREAS
A2: 2 | F2: Medical University of South Carolina | Q2: =$F$2 -> Medical University of South Carolina | T2: =IF(OR(AB247="",AB247=0),"",AB247) | Y2: FIRST,EXP_BLD,FS_KV,REPRO,LIN,HVL_IMGQUAL,OUTPUT,CTPG1
A3: 3 | F3: Charleston, South Carolina | Q3: =$F$3 -> Charleston, South Carolina | T3: =IF(OR(AB248="",AB248=0),"",AB248) | Y3: ALL: | Z3: FIRST,COMPG1,COMPG2,EXP_BLD,FS_KV,TIM,REPRO,LIN,HVL_IMGQUAL,OUTPUT,CTPG1
A4: 4 | T4: =IF(OR(AB249="",AB249=0),"",AB249) | AA4: REM: | AB4: (1) Go to last year's spreadsheet (see "**Note", below) and copy from ITS "THIS YEAR" range
A5: 5 | F5: Radiation Oncology IGRT Compliance Inspection | P5: =$F$5 -> Radiation Oncology IGRT Compliance Inspection | T5: =IF(OR(AB250="",AB250=0),"",AB250) | AB5: (2) Come back to this sheet and paste (use paste special, "values") into "LAST YEAR" range
A6: 6 | T6: =IF(OR(AB251="",AB251=0),"",AB251) | AB6: LAST | AC6: Cell AD6 | AD6: THIS
A7: 7 | AA7: Measurement Parameter | AB7: YEAR | AD7: YEAR | AE7: (Locked) | AF7: RANGES: | AG7: LASTYEAR (Data, starting with cell AB8)
A8: 8 | F8: System Information | N8: Date: | R8: =$F$8 -> System Information | U8: Inspector: | V8: Eugene Mah | AA8: Print Area: | AC8: =IF(AND(OR(AB8="",AB8=0),OR(AD8="",AD8=0)),"",IF(AB8<>AD8,"Change","")) -> Change | AD8: =IF(Y2="","",Y2) -> FIRST,EXP_BLD,FS_KV,REPRO,LIN,HVL_IMGQUAL,OUTPUT,CTPG1 | AE8: Y2 | AG8: THISYEAR (Data, starting with cell AD8)
A9: 9 | N9: Last Year: | O9: =IF(OR(AB9=0,AB9=""),"",AB9) | U9: Last Year: | V9: =IF(OR(AB10=0,AB10=""),"",AB10) | AA9: Date: | AC9: =IF(AND(OR(AB9="",AB9=0),OR(AD9="",AD9=0)),"",IF(AB9<>AD9,"Change","")) | AD9: =IF(O8="","",O8) | AE9: O8
A10: 10 | C10: Location | N10: Location | Q10: Input Changes Only | U10: Input Changes Only | AA10: Inspector: | AC10: =IF(AND(OR(AB10="",AB10=0),OR(AD10="",AD10=0)),"",IF(AB10<>AD10,"Change","")) -> Change | AD10: =IF(V8="","",V8) -> Eugene Mah | AE10: V8
A11: 11 | D11: Facility: | E11: =IF(P11="","",P11) | H11: Site: | I11: =IF(T11="","",T11) | O11: Facility: | P11: =IF(Q11<>"",Q11,IF(OR(AB11=0,AB11=""),"",AB11)) | S11: Site Number: | T11: =IF(U11<>"",U11,IF(OR(AB38=0,AB38=""),"",AB38)) | AA11: =IF(O11="","",O11) -> Facility: | AC11: =IF(AND(OR(AB11="",AB11=0),OR(AD11="",AD11=0)),"",IF(AB11<>AD11,"Change","")) | AD11: =IF(P11="","",P11) | AE11: P11
A12: 12 | D12: Department: | E12: =IF(P12="","",P12) | H12: Authorized Use: | I12: =IF(T12="","",T12) | O12: Department: | P12: =IF(Q12<>"",Q12,IF(OR(AB12=0,AB12=""),"",AB12)) | S12: Authorized Use: | T12: =IF(U12<>"",U12,IF(OR(AB39=0,AB39=""),"",AB39)) | AA12: =IF(O12="","",O12) -> Department: | AC12: =IF(AND(OR(AB12="",AB12=0),OR(AD12="",AD12=0)),"",IF(AB12<>AD12,"Change","")) | AD12: =IF(P12="","",P12) | AE12: P12
A13: 13 | D13: Area/Division: | E13: =IF(P13="","",P13) | H13: Date of Installation: | I13: =IF(T13="","",T13) | O13: Area/Division: | P13: =IF(Q13<>"",Q13,IF(OR(AB13=0,AB13=""),"",AB13)) | S13: Date of Installation: | T13: =IF(U13<>"",U13,IF(OR(AB40=0,AB40=""),"",AB40)) | AA13: =IF(O13="","",O13) -> Area/Division: | AC13: =IF(AND(OR(AB13="",AB13=0),OR(AD13="",AD13=0)),"",IF(AB13<>AD13,"Change","")) | AD13: =IF(P13="","",P13) | AE13: P13
A14: 14 | D14: Survey ID: | E14: =IF(P14="","",P14) | H14: Number of X-ray Tubes: | I14: =IF(T14="","",T14) | O14: Survey ID: | P14: =IF(Q14<>"",Q14,IF(OR(AB14=0,AB14=""),"",AB14)) | S14: Number of X-ray Tubes: | T14: =IF(U14<>"",U14,IF(OR(AB41=0,AB41=""),"",AB41)) | AA14: =IF(O14="","",O14) -> Survey ID: | AC14: =IF(AND(OR(AB14="",AB14=0),OR(AD14="",AD14=0)),"",IF(AB14<>AD14,"Change","")) | AD14: =IF(P14="","",P14) | AE14: P14
A15: 15 | O15: Room Number: | P15: =IF(Q15<>"",Q15,IF(OR(AB15=0,AB15=""),"",AB15)) | S15: Accession Number: | T15: =IF(U15<>"",U15,IF(OR(AB42=0,AB42=""),"",AB42)) | AA15: =IF(O15="","",O15) -> Room Number: | AC15: =IF(AND(OR(AB15="",AB15=0),OR(AD15="",AD15=0)),"",IF(AB15<>AD15,"Change","")) | AD15: =IF(P15="","",P15) | AE15: P15
A16: 16 | AA16: =IF(O16="","",O16) | AC16: =IF(AND(OR(AB16="",AB16=0),OR(AD16="",AD16=0)),"",IF(AB16<>AD16,"Change",""))
A17: 17 | C17: X-Ray Generator | N17: X-Ray Generator | AA17: X-Ray Generator | AC17: =IF(AND(OR(AB17="",AB17=0),OR(AD17="",AD17=0)),"",IF(AB17<>AD17,"Change",""))
A18: 18 | D18: Manufacturer: | E18: =IF(P18="","",P18) | H18: Date of Manufacture: | I18: =IF(T18="","",T18) | O18: Manufacturer: | P18: =IF(Q18<>"",Q18,IF(OR(AB18=0,AB18=""),"",AB18)) | S18: Date of Manufacture: | T18: =IF(U18<>"",U18,IF(OR(AB22=0,AB22=""),"",AB22)) | AA18: =IF(O18="","",O18) -> Manufacturer: | AC18: =IF(AND(OR(AB18="",AB18=0),OR(AD18="",AD18=0)),"",IF(AB18<>AD18,"Change","")) | AD18: =IF(P18="","",P18) | AE18: P18
A19: 19 | D19: Model: | E19: =IF(P19="","",P19) | H19: Serial Number: | I19: =IF(T19="","",T19) | O19: Model: | P19: =IF(Q19<>"",Q19,IF(OR(AB19=0,AB19=""),"",AB19)) | S19: Serial Number: | T19: =IF(U19<>"",U19,IF(OR(AB23=0,AB23=""),"",AB23)) | AA19: =IF(O19="","",O19) -> Model: | AC19: =IF(AND(OR(AB19="",AB19=0),OR(AD19="",AD19=0)),"",IF(AB19<>AD19,"Change","")) | AD19: =IF(P19="","",P19) | AE19: P19
A20: 20 | D20: Max. kVp: | E20: =IF(P20="","",P20) | H20: Max. mA: | I20: =IF(T20="","",T20) | O20: Max. kVp: | P20: =IF(Q20<>"",Q20,IF(OR(AB20=0,AB20=""),"",AB20)) | S20: Max. mA: | T20: =IF(U20<>"",U20,IF(OR(AB24=0,AB24=""),"",AB24)) | AA20: =IF(O20="","",O20) -> Max. kVp: | AC20: =IF(AND(OR(AB20="",AB20=0),OR(AD20="",AD20=0)),"",IF(AB20<>AD20,"Change","")) | AD20: =IF(P20="","",P20) | AE20: P20
A21: 21 | D21: Software Version: | E21: =IF(P21="","",P21) | O21: Software Version: | P21: =IF(Q21<>"",Q21,IF(OR(AB21=0,AB21=""),"",AB21)) | AA21: =IF(O21="","",O21) -> Software Version: | AC21: =IF(AND(OR(AB21="",AB21=0),OR(AD21="",AD21=0)),"",IF(AB21<>AD21,"Change","")) | AD21: =IF(P21="","",P21) | AE21: P21
A22: 22 | AA22: =IF(S18="","",S18) -> Date of Manufacture: | AC22: =IF(AND(OR(AB22="",AB22=0),OR(AD22="",AD22=0)),"",IF(AB22<>AD22,"Change","")) | AD22: =IF(T18="","",T18) | AE22: T18
A23: 23 | C23: =IF(N23="","",N23) -> X-Ray Tube 1 | I23: Focal Spot Sizes | N23: X-Ray Tube 1 | T23: Focal Spot Sizes (mm) | AA23: =IF(S19="","",S19) -> Serial Number: | AC23: =IF(AND(OR(AB23="",AB23=0),OR(AD23="",AD23=0)),"",IF(AB23<>AD23,"Change","")) | AD23: =IF(T19="","",T19) | AE23: T19
A24: 24 | D24: Tube Designation/Use: | E24: =IF(P24="","",P24) | H24: =IF(S24="","",S24) -> Large: | I24: =IF(T24="","",T24) | O24: Tube Designation/Use: | P24: =IF(Q24<>"",Q24,IF(OR(AB27=0,AB27=""),"",AB27)) | S24: Large: | T24: =IF(U24<>"",U24,IF(OR(AB45=0,AB45=""),"",AB45)) | AA24: =IF(S20="","",S20) -> Max. mA: | AC24: =IF(AND(OR(AB24="",AB24=0),OR(AD24="",AD24=0)),"",IF(AB24<>AD24,"Change","")) | AD24: =IF(T20="","",T20) | AE24: T20
A25: 25 | D25: Date of Manufacture: | E25: =IF(P25="","",P25) | H25: =IF(S25="","",S25) -> Small: | I25: =IF(T25="","",T25) | O25: Date of Manufacture: | P25: =IF(Q25<>"",Q25,IF(OR(AB28=0,AB28=""),"",AB28)) | S25: Small: | T25: =IF(U25<>"",U25,IF(OR(AB46=0,AB46=""),"",AB46))
A26: 26 | H26: =IF(T26="","",S26) | I26: =IF(T26="","",T26) | S26: Micro: | T26: =IF(U26<>"",U26,IF(OR(AB47=0,AB47=""),"",AB47)) | AA26: X-Ray Tube 1 | AC26: =IF(AND(OR(AB26="",AB26=0),OR(AD26="",AD26=0)),"",IF(AB26<>AD26,"Change",""))
A27: 27 | D27: Insert Manufacturer: | E27: =IF(P27="","",P27) | I27: Filtration | O27: Insert Manufacturer: | P27: =IF(Q27<>"",Q27,IF(OR(AB30=0,AB30=""),"",AB30)) | T27: Filtration | AA27: =IF(O24="","",O24) -> Tube Designation/Use: | AC27: =IF(AND(OR(AB27="",AB27=0),OR(AD27="",AD27=0)),"",IF(AB27<>AD27,"Change","")) | AD27: =IF(P24="","",P24) | AE27: P24
A28: 28 | D28: Insert Model: | E28: =IF(P28="","",P28) | H28: Inherent: | I28: =IF(T28="","",T28) | O28: Insert Model: | P28: =IF(Q28<>"",Q28,IF(OR(AB31=0,AB31=""),"",AB31)) | S28: Inherent: | T28: =IF(U28<>"",U28,IF(OR(AB49=0,AB49=""),"",AB49)) | AA28: =IF(O25="","",O25) -> Date of Manufacture: | AC28: =IF(AND(OR(AB28="",AB28=0),OR(AD28="",AD28=0)),"",IF(AB28<>AD28,"Change","")) | AD28: =IF(P25="","",P25) | AE28: P25
A29: 29 | D29: Insert Serial Number: | E29: =IF(P29="","",P29) | H29: Added: | I29: =IF(T29="","",T29) | O29: Insert Serial Number: | P29: =IF(Q29<>"",Q29,IF(OR(AB32=0,AB32=""),"",AB32)) | S29: Added: | T29: =IF(U29<>"",U29,IF(OR(AB50=0,AB50=""),"",AB50)) | AA29: =IF(O26="","",O26) | AC29: =IF(AND(OR(AB29="",AB29=0),OR(AD29="",AD29=0)),"",IF(AB29<>AD29,"Change",""))
A30: 30 | AA30: =IF(O27="","",O27) -> Insert Manufacturer: | AC30: =IF(AND(OR(AB30="",AB30=0),OR(AD30="",AD30=0)),"",IF(AB30<>AD30,"Change","")) | AD30: =IF(P27="","",P27) | AE30: P27
A31: 31 | D31: Housing Manufacturer: | E31: =IF(P31="","",P31) | I31: Image Receptor | O31: Housing Manufacturer: | P31: =IF(Q31<>"",Q31,IF(OR(AB34=0,AB34=""),"",AB34)) | T31: Image Receptor | AA31: =IF(O28="","",O28) -> Insert Model: | AC31: =IF(AND(OR(AB31="",AB31=0),OR(AD31="",AD31=0)),"",IF(AB31<>AD31,"Change","")) | AD31: =IF(P28="","",P28) | AE31: P28
A32: 32 | D32: Housing Model: | E32: =IF(P32="","",P32) | H32: Film: | I32: =IF(T32="","",T32) | O32: Housing Model: | P32: =IF(Q32<>"",Q32,IF(OR(AB35=0,AB35=""),"",AB35)) | S32: Film: | T32: =IF(U32<>"",U32,IF(OR(AB53=0,AB53=""),"",AB53)) | AA32: =IF(O29="","",O29) -> Insert Serial Number: | AC32: =IF(AND(OR(AB32="",AB32=0),OR(AD32="",AD32=0)),"",IF(AB32<>AD32,"Change","")) | AD32: =IF(P29="","",P29) | AE32: P29
A33: 33 | D33: Housing Serial Number: | E33: =IF(P33="","",P33) | H33: Screen: | I33: =IF(T33="","",T33) | O33: Housing Serial Number: | P33: =IF(Q33<>"",Q33,IF(OR(AB36=0,AB36=""),"",AB36)) | S33: Screen: | T33: =IF(U33<>"",U33,IF(OR(AB54=0,AB54=""),"",AB54)) | AA33: =IF(O30="","",O30) | AC33: =IF(AND(OR(AB33="",AB33=0),OR(AD33="",AD33=0)),"",IF(AB33<>AD33,"Change",""))
A34: 34 | AA34: =IF(O31="","",O31) -> Housing Manufacturer: | AC34: =IF(AND(OR(AB34="",AB34=0),OR(AD34="",AD34=0)),"",IF(AB34<>AD34,"Change","")) | AD34: =IF(P31="","",P31) | AE34: P31
A35: 35 | AA35: =IF(O32="","",O32) -> Housing Model: | AC35: =IF(AND(OR(AB35="",AB35=0),OR(AD35="",AD35=0)),"",IF(AB35<>AD35,"Change","")) | AD35: =IF(P32="","",P32) | AE35: P32
A36: 36 | AA36: =IF(O33="","",O33) -> Housing Serial Number: | AC36: =IF(AND(OR(AB36="",AB36=0),OR(AD36="",AD36=0)),"",IF(AB36<>AD36,"Change","")) | AD36: =IF(P33="","",P33) | AE36: P33
A37: 37 | AA37: =IF(O34="","",O34) | AC37: =IF(AND(OR(AB37="",AB37=0),OR(AD37="",AD37=0)),"",IF(AB37<>AD37,"Change",""))
A38: 38 | AA38: =IF(S11="","",S11) -> Site Number: | AC38: =IF(AND(OR(AB38="",AB38=0),OR(AD38="",AD38=0)),"",IF(AB38<>AD38,"Change","")) | AD38: =IF(T11="","",T11) | AE38: T11
A39: 39 | AA39: =IF(S12="","",S12) -> Authorized Use: | AC39: =IF(AND(OR(AB39="",AB39=0),OR(AD39="",AD39=0)),"",IF(AB39<>AD39,"Change","")) | AD39: =IF(T12="","",T12) | AE39: T12
A40: 40 | AA40: =IF(S13="","",S13) -> Date of Installation: | AC40: =IF(AND(OR(AB40="",AB40=0),OR(AD40="",AD40=0)),"",IF(AB40<>AD40,"Change","")) | AD40: =IF(T13="","",T13) | AE40: T13
...

Sheet Tables
A1: Huttner Grating | E1: RADIOGRAPHIC UNITS (MUSC CRITERIA) | J1: RAD / DENTAL UNITS (DHEC CRITERIA)
A2: 1.1 | B2: 0.5 | E2: Criteria: | J2: Criteria:
A3: 1.2 | B3: 0.56 | E3: HVL | F3: MIN. HVL | G3: MAX. HVL | J3: HVL | K3: MIN. HVL | L3: MAX. HVL
A4: 1.3 | B4: 0.63 | D4: kVp | E4: (mm Al) | F4: (mm Al) | G4: (mm Al) | I4: kVp | J4: (mm Al) | K4: (mm Al) | L4: (mm Al)
A5: 2.1 | B5: 0.71 | D5: 60 | E5: 2.1854545 | F5: =TRUNC(TREND($E$5:$E$12,$D$5:$D$12,0.9*D5),1) -> 1.9 | G5: =MAX(TRUNC(TREND($E$5:$E$12,$D$5:$D$12,1.1*D5),1),ROUND(TREND($E$5:$E$12,$D$5:$D$12,1.1*D5),1)) -> 2.4 | I5: 50 | J5: 1.5 | K5: 1.5 | L5: 1.7
A6: 2.2 | B6: 0.8 | D6: 70 | E6: 2.6109091 | F6: =TRUNC(TREND($E$5:$E$12,$D$5:$D$12,0.9*D6),1) -> 2.3 | G6: =MAX(TRUNC(TREND($E$5:$E$12,$D$5:$D$12,1.1*D6),1),ROUND(TREND($E$5:$E$12,$D$5:$D$12,1.1*D6),1)) -> 2.9 | I6: 60 | J6: 1.5 | K6: 1.5 | L6: 1.7
A7: 2.3 | B7: 0.9 | D7: 80 | E7: 3.0363636 | F7: =TRUNC(TREND($E$5:$E$12,$D$5:$D$12,0.9*D7),1) -> 2.6 | G7: =MAX(TRUNC(TREND($E$5:$E$12,$D$5:$D$12,1.1*D7),1),ROUND(TREND($E$5:$E$12,$D$5:$D$12,1.1*D7),1)) -> 3.4 | I7: 70 | J7: 1.5 | K7: 1.5 | L7: 1.7
A8: 3.1 | B8: 1 | D8: 90 | E8: 3.4618182 | F8: =TRUNC(TREND($E$5:$E$12,$D$5:$D$12,0.9*D8),1) -> 3 | G8: =MAX(TRUNC(TREND($E$5:$E$12,$D$5:$D$12,1.1*D8),1),ROUND(TREND($E$5:$E$12,$D$5:$D$12,1.1*D8),1)) -> 3.8 | I8: 80 | J8: 2.3 | K8: 2.3 | L8: 2.7
A9: 3.2 | B9: 1.12 | D9: 100 | E9: 3.8872727 | F9: =TRUNC(TREND($E$5:$E$12,$D$5:$D$12,0.9*D9),1) -> 3.4 | G9: =MAX(TRUNC(TREND($E$5:$E$12,$D$5:$D$12,1.1*D9),1),ROUND(TREND($E$5:$E$12,$D$5:$D$12,1.1*D9),1)) -> 4.3 | I9: 90 | J9: 2.5 | K9: 2.5 | L9: 3
A10: 3.3 | B10: 1.25 | D10: 110 | E10: 4.3127273 | F10: =TRUNC(TREND($E$5:$E$12,$D$5:$D$12,0.9*D10),1) -> 3.8 | G10: =MAX(TRUNC(TREND($E$5:$E$12,$D$5:$D$12,1.1*D10),1),ROUND(TREND($E$5:$E$12,$D$5:$D$12,1.1*D10),1)) -> 4.8 | I10: 100 | J10: 2.7 | K10: 2.7 | L10: 3.2
A11: 4.1 | B11: 1.4 | D11: 120 | E11: 4.7381818 | F11: =TRUNC(TREND($E$5:$E$12,$D$5:$D$12,0.9*D11),1) -> 4.2 | G11: =MAX(TRUNC(TREND($E$5:$E$12,$D$5:$D$12,1.1*D11),1),ROUND(TREND($E$5:$E$12,$D$5:$D$12,1.1*D11),1)) -> 5.2 | I11: 110 | J11: 3 | K11: 3 | L11: 3.5
A12: 4.2 | B12: 1.6 | D12: 130 | E12: 5.1636364 | F12: =TRUNC(TREND($E$5:$E$12,$D$5:$D$12,0.9*D12),1) -> 4.6 | G12: =MAX(TRUNC(TREND($E$5:$E$12,$D$5:$D$12,1.1*D12),1),ROUND(TREND($E$5:$E$12,$D$5:$D$12,1.1*D12),1)) -> 5.7 | I12: 120 | J12: =TREND(J8:J11,I8:I11,I12) -> 3.2 | K12: 3.2 | L12: =TREND(L8:L11,I8:I11,I12) -> 3.75
A13: 4.3 | B13: 1.8
A14: 5.1 | B14: 2
A15: 5.2 | B15: 2.24
A16: 5.3 | B16: 2.5
A17: 6.1 | B17: 2.8
A18: 6.2 | B18: 3.15
A19: 6.3 | B19: 3.55
A20: 7.1 | B20: 4
A21: 7.2 | B21: 4.5
A22: 7.3 | B22: 5
A24: RTI Piranha
A25: Piranha 1 | B25: Piranha 1 CB2-17090320
A26: Piranha 2 | B26: Piranha 2 CB2-19020491
A28: RTI DAP chamber
A29: DAP 1 | B29: DAP 1 2501554
A30: DAP 2 | B30: DAP 2 2501555

Sheet Sheet1
A1: Measurements | Q1: 125 kV Half Fan | R1: 125 kV Full fan | S1: 140 kV Half fan | T1: 100 kV full fan | X1: Measurements
P2: kV | Q2: 125 | R2: 125 | S2: 140 | T2: 100
A3: Set kV_x000D_(kV) | B3: Set mA_x000D_(mA) | C3: Set mAs_x000D_(mAs) | D3: Set time_x000D_(s) | E3: Added Filt | F3: Focal spot | G3: Tube voltage_x000D_(kV) | H3: Exposure time_x000D_(s) | I3: Exposure_x000D_(mGy) | J3: Exposure rate_x000D_(mGy/s) | K3: Total filtr._x000D_(mm Al) | L3: HVL_x000D_(mm Al) | M3: Exposure (norm)_x000D_(mGy) | N3: Exposure rate (norm)_x000D_(mGy/s) | P3: mAs/pulse | Q3: 1.2 | R3: 1.2 | S3: 1.88 | T3: 0.3 | X3: Set kV_x000D_(kV) | Y3: CT phantom type | Z3: Set Added filtr._x000D_(mm Al) | AA3: Exposure time_x000D_(ms) | AB3: Exposure_x000D_(mGy) | AC3: Exposure rate_x000D_(mGy/s)
A4: 60 | B4: 400 | C4: 20 | D4: 0.05 | E4: 0 | F4: Large | P4: Pulse mA | Q4: 60 | R4: 60 | S4: 75 | T4: 15
A5: 80 | B5: 400 | C5: 20 | D5: 0.05 | E5: 0 | F5: Large | P5: Pulse ms | Q5: 20 | R5: 20 | S5: 25 | T5: 20
A6: 80 | B6: 400 | C6: 20 | D6: 0.05 | E6: 0 | F6: Large | P6: Pulse rate | Q6: 15 | R6: 15 | S6: 15 | T6: 15
A7: 80 | B7: 400 | C7: 20 | D7: 0.05 | E7: 0 | F7: Large | P7: X1 | Q7: -24.7 | R7: -14 | S7: -24.7 | T7: -14
A8: 80 | B8: 400 | C8: 20 | D8: 0.05 | E8: 0 | F8: Large | P8: X2 | Q8: 3.3 | R8: 14 | S8: 3.3 | T8: 14
A9: 80 | B9: 400 | C9: 20 | D9: 0.05 | E9: 0 | F9: Large | P9: Y1 | Q9: -10.7 | R9: -10.7 | S9: -10.7 | T9: -10.7
A10: 80 | B10: 400 | C10: 20 | D10: 0.05 | E10: 3 | F10: Large | P10: Y2 | Q10: 10.7 | R10: 10.7 | S10: 10.7 | T10: 10.7
A11: 80 | B11: 400 | C11: 20 | D11: 0.05 | E11: 3 | F11: Large
A12: 80 | B12: 400 | C12: 20 | D12: 0.05 | E12: 3.5 | F12: Large | P12: Center
A13: 80 | B13: 400 | C13: 20 | D13: 0.05 | E13: 3.5 | F13: Large | P13: Top
A14: 80 | B14: 400 | C14: 20 | D14: 0.05 | E14: 2.5 | F14: Large | P14: Bottom
A15: 80 | B15: 400 | C15: 20 | D15: 0.05 | E15: 2.5 | F15: Large | P15: Left
A16: 80 | B16: 500 | C16: 25 | D16: 0.05 | E16: 0 | F16: Large | P16: Right
A17: 80 | B17: 50 | C17: 2.5 | D17: 0.05 | E17: 0 | F17: Large
A18: 80 | B18: 800 | C18: 40 | D18: 0.05 | E18: 0 | F18: Large
A19: 80 | B19: 250 | C19: 12.5 | D19: 0.05 | E19: 0 | F19: Large
A20: 100 | B20: 400 | C20: 20 | D20: 0.05 | E20: 0 | F20: Large
A21: 120 | B21: 400 | C21: 20 | D21: 0.05 | E21: 0 | F21: Large
A22: 140 | B22: 400 | C22: 20 | D22: 0.05 | E22: 0 | F22: Large
A23: 50 | B23: 100 | C23: 10 | D23: 0.1 | E23: 0 | F23: Small
A24: 70 | B24: 100 | C24: 10 | D24: 0.1 | E24: 0 | F24: Small
A25: 90 | B25: 100 | C25: 10 | D25: 0.1 | E25: 0 | F25: Small
A26: 90 | B26: 100 | C26: 10 | D26: 0.1 | E26: 0 | F26: Small
A27: 90 | B27: 100 | C27: 10 | D27: 0.1 | E27: 0 | F27: Small
A28: 90 | B28: 100 | C28: 10 | D28: 0.1 | E28: 0 | F28: Small
... A42: 80 | B42: 200 | C42: 80 | D42: 0.4 | E42: 0 | F42: Large
A44: Waveforms

Sheet DataPage
A1: Sheet | B1: RAD
A2: SurveyID | B2: =Gen_form!E14
A3: LFS | B3: =Gen_form!U209 -> 0
A4: SFS | B4: =Gen_form!U214 -> 0
A5: Collimation table | B5: =Gen_form!B314 -> 5 | C5: =Gen_form!C314 -> 5 | D5: =Gen_form!D314 | E5: =Gen_form!E314
B6: =Gen_form!B315 -> 10 | C6: =Gen_form!C315 -> 10 | D6: =Gen_form!D315 | E6: =Gen_form!E315
A7: LFS Output | B7: =Gen_form!D668 | C7: =Gen_form!E668
B8: =Gen_form!D669 | C8: =Gen_form!E669
B9: =Gen_form!D670 | C9: =Gen_form!E670
B10: =Gen_form!D671 | C10: =Gen_form!E671
B11: =Gen_form!D672 | C11: =Gen_form!E672
B12: =Gen_form!D673 | C12: =Gen_form!E673
B13: =Gen_form!D674 | C13: =Gen_form!E674
B14: =Gen_form!D675 | C14: =Gen_form!E675
A15: SFS Output | B15: =Gen_form!D681 | C15: =Gen_form!E681
B16: =Gen_form!D682 | C16: =Gen_form!E682
B17: =Gen_form!D683 | C17: =Gen_form!E683
B18: =Gen_form!D684 | C18: =Gen_form!E684
B19: =Gen_form!D685 | C19: =Gen_form!E685
B20: =Gen_form!D686 | C20: =Gen_form!E686
A21: Gen Test | B21: =Tables!B49 -> 0 | C21: =Tables!C49 -> 0 | D21: =Tables!D49 -> 0 | E21: =Tables!E49 -> 0 | F21: =Tables!F49 -> 0 | G21: =Tables!G49 -> 0 | H21: =Tables!H49 -> 0 | I21: =Tables!I49 -> 0 | ... AC21: =Tables!AC49 -> 0
B22: =Tables!B50 -> 0 | C22: =Tables!C50 -> 0 | D22: =Tables!D50 -> 0 | E22: =Tables!E50 -> 0 | F22: =Tables!F50 -> 0 | G22: =Tables!G50 -> 0 | H22: =Tables!H50 -> 0 | I22: =Tables!I50 -> 0 | ... AC22: =Tables!AC50 -> 0
B23: =Tables!B51 -> 0 | C23: =Tables!C51 -> 0 | D23: =Tables!D51 -> 0 | E23: =Tables!E51 -> 0 | F23: =Tables!F51 -> 0 | G23: =Tables!G51 -> 0 | H23: =Tables!H51 -> 0 | I23: =Tables!I51 -> 0 | ... AC23: =Tables!AC51 -> 0
B24: =Tables!B52 -> 0 | C24: =Tables!C52 -> 0 | D24: =Tables!D52 -> 0 | E24: =Tables!E52 -> 0 | F24: =Tables!F52 -> 0 | G24: =Tables!G52 -> 0 | H24: =Tables!H52 -> 0 | I24: =Tables!I52 -> 0 | ... AC24: =Tables!AC52 -> 0
B25: =Tables!B53 -> 0 | C25: =Tables!C53 -> 0 | D25: =Tables!D53 -> 0 | E25: =Tables!E53 -> 0 | F25: =Tables!F53 -> 0 | G25: =Tables!G53 -> 0 | H25: =Tables!H53 -> 0 | I25: =Tables!I53 -> 0 | ... AC25: =Tables!AC53 -> 0
B26: =Tables!B54 -> 0 | C26: =Tables!C54 -> 0 | D26: =Tables!D54 -> 0 | E26: =Tables!E54 -> 0 | F26: =Tables!F54 -> 0 | G26: =Tables!G54 -> 0 | H26: =Tables!H54 -> 0 | I26: =Tables!I54 -> 0 | ... AC26: =Tables!AC54 -> 0
B27: =Tables!B55 -> 0 | C27: =Tables!C55 -> 0 | D27: =Tables!D55 -> 0 | E27: =Tables!E55 -> 0 | F27: =Tables!F55 -> 0 | G27: =Tables!G55 -> 0 | H27: =Tables!H55 -> 0 | I27: =Tables!I55 -> 0 | ... AC27: =Tables!AC55 -> 0
B28: =Tables!B56 -> 0 | C28: =Tables!C56 -> 0 | D28: =Tables!D56 -> 0 | E28: =Tables!E56 -> 0 | F28: =Tables!F56 -> 0 | G28: =Tables!G56 -> 0 | H28: =Tables!H56 -> 0 | I28: =Tables!I56 -> 0 | ... AC28: =Tables!AC56 -> 0
B29: =Tables!B57 -> 0 | C29: =Tables!C57 -> 0 | D29: =Tables!D57 -> 0 | E29: =Tables!E57 -> 0 | F29: =Tables!F57 -> 0 | G29: =Tables!G57 -> 0 | H29: =Tables!H57 -> 0 | I29: =Tables!I57 -> 0 | ... AC29: =Tables!AC57 -> 0
B30: =Tables!B58 -> 0 | C30: =Tables!C58 -> 0 | D30: =Tables!D58 -> 0 | E30: =Tables!E58 -> 0 | F30: =Tables!F58 -> 0 | G30: =Tables!G58 -> 0 | H30: =Tables!H58 -> 0 | I30: =Tables!I58 -> 0 | ... AC30: =Tables!AC58 -> 0
B31: =Tables!B59 -> 0 | C31: =Tables!C59 -> 0 | D31: =Tables!D59 -> 0 | E31: =Tables!E59 -> 0 | F31: =Tables!F59 -> 0 | G31: =Tables!G59 -> 0 | H31: =Tables!H59 -> 0 | I31: =Tables!I59 -> 0 | ... AC31: =Tables!AC59 -> 0
B32: =Tables!B60 -> 0 | C32: =Tables!C60 -> 0 | D32: =Tables!D60 -> 0 | E32: =Tables!E60 -> 0 | F32: =Tables!F60 -> 0 | G32: =Tables!G60 -> 0 | H32: =Tables!H60 -> 0 | I32: =Tables!I60 -> 0 | ... AC32: =Tables!AC60 -> 0
B33: =Tables!B61 -> 0 | C33: =Tables!C61 -> 0 | D33: =Tables!D61 -> 0 | E33: =Tables!E61 -> 0 | F33: =Tables!F61 -> 0 | G33: =Tables!G61 -> 0 | H33: =Tables!H61 -> 0 | I33: =Tables!I61 -> 0 | ... AC33: =Tables!AC61 -> 0
... B62: =Tables!B90 -> 0 | C62: =Tables!C90 -> 0 | D62: =Tables!D90 -> 0 | E62: =Tables!E90 -> 0 | F62: =Tables!F90 -> 0 | G62: =Tables!G90 -> 0 | H62: =Tables!H90 -> 0 | I62: =Tables!I90 -> 0 | ... AC62: =Tables!AC90 -> 0
A63: HVL | B63: =Gen_form!#REF! -> #REF! | C63: =Gen_form!#REF! -> #REF!
B64: =Gen_form!#REF! -> #REF! | C64: =Gen_form!#REF! -> #REF!
B65: =Gen_form!#REF! -> #REF! | C65: =Gen_form!#REF! -> #REF!
B66: =Gen_form!#REF! -> #REF! | C66: =Gen_form!#REF! -> #REF!
B67: =Gen_form!#REF! -> #REF! | C67: =Gen_form!#REF! -> #REF!
B68: =Gen_form!#REF! -> #REF! | C68: =Gen_form!#REF! -> #REF!
...
