Workbook
Name AEC_KAP: Sheet1!$B$442:$J$490
Name BLD: Sheet1!$B$295:$J$343
Name COMPG2: Sheet1!$B$148:$J$196
Name COMPG3: Sheet1!$B$197:$J$245
Name EXP: Sheet1!$B$246:$J$294
Name F_ALUM: Sheet1!$O$401:$O$402
Name F_ALUM_0: Sheet1!$L$401
Name F_ALUM_1: Sheet1!$L$402
Name F_ALUM_2: Sheet1!$L$403
Name F_ALUM_3: Sheet1!$L$404
Name F_ALUMHIGH: Sheet1!$O$402
Name F_ALUMLOW: Sheet1!$O$401
Name F_DHALF: Sheet1!$N$401:$N$404
Name F_EXP_0: Sheet1!$M$401
Name F_EXP_1: Sheet1!$M$402
Name F_EXP_2: Sheet1!$M$403
Name F_EXP_3: Sheet1!$M$404
Name F_HVL: Sheet1!$P$405
Name F_LNEXP: Sheet1!$P$401:$P$402
Name FIRST: Sheet1!$B$1:$J$147
Name FrontalMAS: Sheet1!$O$322
Name KV_REPRO: Sheet1!$B$344:$J$392
Name L_ALUM: Sheet1!$T$401:$T$402
Name L_ALUM_0: Sheet1!$Q$401
Name L_ALUM_1: Sheet1!$Q$402
Name L_ALUM_2: Sheet1!$Q$403
Name L_ALUM_3: Sheet1!$Q$404
Name L_ALUMHIGH: Sheet1!$T$402
Name L_ALUMLOW: Sheet1!$T$401
Name L_DHALF: Sheet1!$S$401:$S$404
Name L_EXP_0: Sheet1!$R$401
Name L_EXP_1: Sheet1!$R$402
Name L_EXP_2: Sheet1!$R$403
Name L_EXP_3: Sheet1!$R$404
Name L_HVL: Sheet1!$U$405
Name L_LNEXP: Sheet1!$U$401:$U$402
Name LAST: Sheet1!$B$491:$J$539
Name LateralMAS: Sheet1!$O$327
Name LIN_HVL: Sheet1!$B$393:$J$441

Sheet Sheet1
A1: 1 | L1: Revision 001-20260415 (Has 48 data records) | X1: PRINT AREAS
A2: 2 | F2: Medical University of South Carolina | P2: =$F$2 -> Medical University of South Carolina | X2: FIRST,EXP,BLD,KV_REPRO,LIN_HVL,AEC_KAP,LAST
A3: 3 | F3: Charleston, South Carolina | P3: =$F$3 -> Charleston, South Carolina | X3: ALL: | Y3: FIRST,COMPG2,COMPG3,EXP,BLD,KV_REPRO,LIN_HVL,AEC_KAP,LAST
A4: 4 | Z4: REM: | AA4: (1) Go to last year's spreadsheet (see "**Note", below) and copy from ITS "THIS YEAR" range
A5: 5 | F5: EOS Imaging System Compliance Inspection | O5: =$F$5 -> EOS Imaging System Compliance Inspection | AA5: (2) Come back to this sheet and paste (use paste special, "values") into "LAST YEAR" range
A6: 6 | AA6: LAST | AB6: Cell AD6 | AC6: THIS
A7: 7 | Z7: Measurement Parameter | AA7: YEAR | AC7: YEAR | AD7: (Locked)
A8: 8 | F8: System Information | M8: Date: | Q8: =$F$8 -> System Information | T8: Inspector: | U8: Eugene Mah | Z8: Print Area: | AB8: =IF(AND(OR(AA8="",AA8=0),OR(AC8="",AC8=0)),"",IF(AA8<>AC8,"Change","")) -> Change | AC8: =IF(X2="","",X2) -> FIRST,EXP,BLD,KV_REPRO,LIN_HVL,AEC_KAP,LAST | AD8: X2
A9: 9 | M9: Last Year: | N9: =IF(OR(AA9=0,AA9=""),"",AA9) | T9: Last Year: | U9: =IF(OR(AA10=0,AA10=""),"",AA10) | Z9: Date: | AB9: =IF(AND(OR(AA9="",AA9=0),OR(AC9="",AC9=0)),"",IF(AA9<>AC9,"Change","")) | AC9: =IF(N8="","",N8) | AD9: N8
A10: 10 | C10: Location | M10: Location | P10: Input Changes Only | T10: Input Changes Only | Z10: Inspector: | AB10: =IF(AND(OR(AA10="",AA10=0),OR(AC10="",AC10=0)),"",IF(AA10<>AC10,"Change","")) -> Change | AC10: =IF(U8="","",U8) -> Eugene Mah | AD10: U8
A11: 11 | D11: Facility: | E11: =IF(O11="","",O11) | H11: Site: | I11: =IF(S11="","",S11) | N11: Facility: | O11: =IF(P11<>"",P11,IF(OR(AA11=0,AA11=""),"",AA11)) | R11: Site Number: | S11: =IF(T11<>"",T11,IF(OR(AA48=0,AA48=""),"",AA48)) | Z11: =IF(N11="","",N11) -> Facility: | AB11: =IF(AND(OR(AA11="",AA11=0),OR(AC11="",AC11=0)),"",IF(AA11<>AC11,"Change","")) | AC11: =IF(O11="","",O11) | AD11: O11
A12: 12 | D12: Department: | E12: =IF(O12="","",O12) | H12: Authorized Use: | I12: =IF(S12="","",S12) | N12: Department: | O12: =IF(P12<>"",P12,IF(OR(AA12=0,AA12=""),"",AA12)) | R12: Authorized Use: | S12: =IF(T12<>"",T12,IF(OR(AA49=0,AA49=""),"",AA49)) | Z12: =IF(N12="","",N12) -> Department: | AB12: =IF(AND(OR(AA12="",AA12=0),OR(AC12="",AC12=0)),"",IF(AA12<>AC12,"Change","")) | AC12: =IF(O12="","",O12) | AD12: O12
A13: 13 | D13: Area/Division: | E13: =IF(O13="","",O13) | H13: Date of Installation: | I13: =IF(S13="","",S13) | N13: Area/Division: | O13: =IF(P13<>"",P13,IF(OR(AA13=0,AA13=""),"",AA13)) | R13: Date of Installation: | S13: =IF(T13<>"",T13,IF(OR(AA50=0,AA50=""),"",AA50)) | Z13: =IF(N13="","",N13) -> Area/Division: | AB13: =IF(AND(OR(AA13="",AA13=0),OR(AC13="",AC13=0)),"",IF(AA13<>AC13,"Change","")) | AC13: =IF(O13="","",O13) | AD13: O13
A14: 14 | D14: Survey ID: | E14: =IF(O14="","",O14) | H14: Number of X-ray Tubes: | I14: =IF(S14="","",S14) -> 2 | N14: Survey ID: | O14: =IF(P14<>"",P14,IF(OR(AA14=0,AA14=""),"",AA14)) | R14: Number of X-ray Tubes: | S14: =IF(T14<>"",T14,IF(OR(AA51=0,AA51=""),"",AA51)) -> 2 | T14: 2 | Z14: =IF(N14="","",N14) -> Survey ID: | AB14: =IF(AND(OR(AA14="",AA14=0),OR(AC14="",AC14=0)),"",IF(AA14<>AC14,"Change","")) | AC14: =IF(O14="","",O14) | AD14: O14
A15: 15 | N15: Room Number: | O15: =IF(P15<>"",P15,IF(OR(AA15=0,AA15=""),"",AA15)) | R15: Accession Number: | S15: =IF(T15<>"",T15,IF(OR(AA52=0,AA52=""),"",AA52)) | Z15: =IF(N15="","",N15) -> Room Number: | AB15: =IF(AND(OR(AA15="",AA15=0),OR(AC15="",AC15=0)),"",IF(AA15<>AC15,"Change","")) | AC15: =IF(O15="","",O15) | AD15: O15
A16: 16 | Z16: =IF(N16="","",N16) | AB16: =IF(AND(OR(AA16="",AA16=0),OR(AC16="",AC16=0)),"",IF(AA16<>AC16,"Change",""))
A17: 17 | C17: X-Ray Generator | M17: X-Ray Generator | Z17: X-Ray Generator | AB17: =IF(AND(OR(AA17="",AA17=0),OR(AC17="",AC17=0)),"",IF(AA17<>AC17,"Change",""))
A18: 18 | D18: Manufacturer: | E18: =IF(O18="","",O18) | H18: Date of Manufacture: | I18: =IF(S18="","",S18) | N18: Manufacturer: | O18: =IF(P18<>"",P18,IF(OR(AA18=0,AA18=""),"",AA18)) | R18: Date of Manufacture: | S18: =IF(T18<>"",T18,IF(OR(AA54=0,AA54=""),"",AA54)) | Z18: =IF(N18="","",N18) -> Manufacturer: | AB18: =IF(AND(OR(AA18="",AA18=0),OR(AC18="",AC18=0)),"",IF(AA18<>AC18,"Change","")) | AC18: =IF(O18="","",O18) | AD18: O18
A19: 19 | D19: Model: | E19: =IF(O19="","",O19) | H19: Serial Number: | I19: =IF(S19="","",S19) | N19: Model: | O19: =IF(P19<>"",P19,IF(OR(AA19=0,AA19=""),"",AA19)) | R19: Serial Number: | S19: =IF(T19<>"",T19,IF(OR(AA55=0,AA55=""),"",AA55)) | Z19: =IF(N19="","",N19) -> Model: | AB19: =IF(AND(OR(AA19="",AA19=0),OR(AC19="",AC19=0)),"",IF(AA19<>AC19,"Change","")) | AC19: =IF(O19="","",O19) | AD19: O19
A20: 20 | D20: Max. kVp: | E20: =IF(O20="","",O20) | H20: Max. mA: | I20: =IF(S20="","",S20) | N20: Max. kVp: | O20: =IF(P20<>"",P20,IF(OR(AA20=0,AA20=""),"",AA20)) | R20: Max. mA: | S20: =IF(T20<>"",T20,IF(OR(AA56=0,AA56=""),"",AA56)) | Z20: =IF(N20="","",N20) -> Max. kVp: | AB20: =IF(AND(OR(AA20="",AA20=0),OR(AC20="",AC20=0)),"",IF(AA20<>AC20,"Change","")) | AC20: =IF(O20="","",O20) | AD20: O20
A21: 21 | D21: Software Version: | E21: =IF(O21="","",O21) | N21: Software Version: | O21: =IF(P21<>"",P21,IF(OR(AA21=0,AA21=""),"",AA21)) | Z21: =IF(N21="","",N21) -> Software Version: | AB21: =IF(AND(OR(AA21="",AA21=0),OR(AC21="",AC21=0)),"",IF(AA21<>AC21,"Change","")) | AC21: =IF(O21="","",O21) | AD21: O21
A22: 22 | Z22: =IF(N22="","",N22) | AB22: =IF(AND(OR(AA22="",AA22=0),OR(AC22="",AC22=0)),"",IF(AA22<>AC22,"Change",""))
A23: 23 | C23: X-Ray Tube 1 (Frontal) | I23: Focal Spot Sizes | M23: X-Ray Tube 1 (Frontal) | S23: Focal Spot Sizes (mm) | Z23: X-Ray Tube 1 | AB23: =IF(AND(OR(AA23="",AA23=0),OR(AC23="",AC23=0)),"",IF(AA23<>AC23,"Change",""))
A24: 24 | D24: Tube Designation/Use: | E24: =IF(O24="","",O24) | H24: Large: | I24: =IF(S24="","",S24) | N24: Tube Designation/Use: | O24: =IF(P24<>"",P24,IF(OR(AA24=0,AA24=""),"",AA24)) | R24: Large: | S24: =IF(T24<>"",T24,IF(OR(AA59=0,AA59=""),"",AA59)) | Z24: =IF(N24="","",N24) -> Tube Designation/Use: | AB24: =IF(AND(OR(AA24="",AA24=0),OR(AC24="",AC24=0)),"",IF(AA24<>AC24,"Change","")) | AC24: =IF(O24="","",O24) | AD24: O24
A25: 25 | D25: Date of Manufacture: | E25: =IF(O25="","",O25) | H25: Small: | I25: =IF(S25="","",S25) | N25: Date of Manufacture: | O25: =IF(P25<>"",P25,IF(OR(AA25=0,AA25=""),"",AA25)) | R25: Small: | S25: =IF(T25<>"",T25,IF(OR(AA60=0,AA60=""),"",AA60)) | Z25: =IF(N25="","",N25) -> Date of Manufacture: | AB25: =IF(AND(OR(AA25="",AA25=0),OR(AC25="",AC25=0)),"",IF(AA25<>AC25,"Change","")) | AC25: =IF(O25="","",O25) | AD25: O25
A26: 26 | H26: Micro: | I26: =IF(S26="","",S26) | R26: Micro: | S26: =IF(T26<>"",T26,IF(OR(AA61=0,AA61=""),"",AA61)) | Z26: =IF(N26="","",N26) | AB26: =IF(AND(OR(AA26="",AA26=0),OR(AC26="",AC26=0)),"",IF(AA26<>AC26,"Change",""))
A27: 27 | D27: Insert Manufacturer: | E27: =IF(O27="","",O27) | I27: Filtration | N27: Insert Manufacturer: | O27: =IF(P27<>"",P27,IF(OR(AA27=0,AA27=""),"",AA27)) | S27: Filtration | Z27: =IF(N27="","",N27) -> Insert Manufacturer: | AB27: =IF(AND(OR(AA27="",AA27=0),OR(AC27="",AC27=0)),"",IF(AA27<>AC27,"Change","")) | AC27: =IF(O27="","",O27) | AD27: O27
A28: 28 | D28: Insert Model: | E28: =IF(O28="","",O28) | H28: Inherent: | I28: =IF(S28="","",S28) | N28: Insert Model: | O28: =IF(P28<>"",P28,IF(OR(AA28=0,AA28=""),"",AA28)) | R28: Inherent: | S28: =IF(T28<>"",T28,IF(OR(AA63=0,AA63=""),"",AA63)) | Z28: =IF(N28="","",N28) -> Insert Model: | AB28: =IF(AND(OR(AA28="",AA28=0),OR(AC28="",AC28=0)),"",IF(AA28<>AC28,"Change","")) | AC28: =IF(O28="","",O28) | AD28: O28
A29: 29 | D29: Insert Serial Number: | E29: =IF(O29="","",O29) | H29: Added: | I29: =IF(S29="","",S29) | N29: Insert Serial Number: | O29: =IF(P29<>"",P29,IF(OR(AA29=0,AA29=""),"",AA29)) | R29: Added: | S29: =IF(T29<>"",T29,IF(OR(AA64=0,AA64=""),"",AA64)) | Z29: =IF(N29="","",N29) -> Insert Serial Number: | AB29: =IF(AND(OR(AA29="",AA29=0),OR(AC29="",AC29=0)),"",IF(AA29<>AC29,"Change","")) | AC29: =IF(O29="","",O29) | AD29: O29
A30: 30 | Z30: =IF(N30="","",N30) | AB30: =IF(AND(OR(AA30="",AA30=0),OR(AC30="",AC30=0)),"",IF(AA30<>AC30,"Change",""))
A31: 31 | D31: Housing Manufacturer: | E31: =IF(O31="","",O31) | N31: Housing Manufacturer: | O31: =IF(P31<>"",P31,IF(OR(AA31=0,AA31=""),"",AA31)) | Z31: =IF(N31="","",N31) -> Housing Manufacturer: | AB31: =IF(AND(OR(AA31="",AA31=0),OR(AC31="",AC31=0)),"",IF(AA31<>AC31,"Change","")) | AC31: =IF(O31="","",O31) | AD31: O31
A32: 32 | D32: Housing Model: | E32: =IF(O32="","",O32) | N32: Housing Model: | O32: =IF(P32<>"",P32,IF(OR(AA32=0,AA32=""),"",AA32)) | Z32: =IF(N32="","",N32) -> Housing Model: | AB32: =IF(AND(OR(AA32="",AA32=0),OR(AC32="",AC32=0)),"",IF(AA32<>AC32,"Change","")) | AC32: =IF(O32="","",O32) | AD32: O32
A33: 33 | D33: Housing Serial Number: | E33: =IF(O33="","",O33) | N33: Housing Serial Number: | O33: =IF(P33<>"",P33,IF(OR(AA33=0,AA33=""),"",AA33)) | Z33: =IF(N33="","",N33) -> Housing Serial Number: | AB33: =IF(AND(OR(AA33="",AA33=0),OR(AC33="",AC33=0)),"",IF(AA33<>AC33,"Change","")) | AC33: =IF(O33="","",O33) | AD33: O33
A34: 34 | Z34: =IF(N34="","",N34) | AB34: =IF(AND(OR(AA34="",AA34=0),OR(AC34="",AC34=0)),"",IF(AA34<>AC34,"Change",""))
A35: 35 | Z35: =IF(N35="","",N35) | AB35: =IF(AND(OR(AA35="",AA35=0),OR(AC35="",AC35=0)),"",IF(AA35<>AC35,"Change",""))
A36: 36 | C36: X-Ray Tube 2 (Lateral) | I36: Focal Spot Sizes | M36: X-Ray Tube 2 (Lateral) | S36: Focal Spot Sizes (mm) | Z36: X-Ray Tube 2 | AB36: =IF(AND(OR(AA36="",AA36=0),OR(AC36="",AC36=0)),"",IF(AA36<>AC36,"Change",""))
A37: 37 | D37: Tube Designation/Use: | E37: =IF(O37="","",O37) | H37: Large: | I37: =IF(S37="","",S37) | N37: Tube Designation/Use: | O37: =IF(P37<>"",P37,IF(OR(AA37=0,AA37=""),"",AA37)) | R37: Large: | S37: =IF(T37<>"",T37,IF(OR(AA67=0,AA67=""),"",AA67)) | Z37: =IF(N37="","",N37) -> Tube Designation/Use: | AB37: =IF(AND(OR(AA37="",AA37=0),OR(AC37="",AC37=0)),"",IF(AA37<>AC37,"Change","")) | AC37: =IF(O37="","",O37) | AD37: O37
A38: 38 | D38: Date of Manufacture: | E38: =IF(O38="","",O38) | H38: Small: | I38: =IF(S38="","",S38) | N38: Date of Manufacture: | O38: =IF(P38<>"",P38,IF(OR(AA38=0,AA38=""),"",AA38)) | R38: Small: | S38: =IF(T38<>"",T38,IF(OR(AA68=0,AA68=""),"",AA68)) | Z38: =IF(N38="","",N38) -> Date of Manufacture: | AB38: =IF(AND(OR(AA38="",AA38=0),OR(AC38="",AC38=0)),"",IF(AA38<>AC38,"Change","")) | AC38: =IF(O38="","",O38) | AD38: O38
A39: 39 | H39: Micro: | I39: =IF(S39="","",S39) | J39: =IF(T39="","",U39) | R39: Micro: | S39: =IF(T39<>"",T39,IF(OR(AA69=0,AA69=""),"",AA69)) | Z39: =IF(N39="","",N39) | AB39: =IF(AND(OR(AA39="",AA39=0),OR(AC39="",AC39=0)),"",IF(AA39<>AC39,"Change",""))
A40: 40 | D40: Insert Manufacturer: | E40: =IF(O40="","",O40) | I40: Filtration | N40: Insert Manufacturer: | O40: =IF(P40<>"",P40,IF(OR(AA40=0,AA40=""),"",AA40)) | S40: Filtration | Z40: =IF(N40="","",N40) -> Insert Manufacturer: | AB40: =IF(AND(OR(AA40="",AA40=0),OR(AC40="",AC40=0)),"",IF(AA40<>AC40,"Change","")) | AC40: =IF(O40="","",O40) | AD40: O40
...

Sheet Frontal Gen
A1: Frontal tube
A2: Measurements
A4: Set kV_x000D_(kV) | B4: Set mA_x000D_(mA) | C4: Set mAs_x000D_(mAs) | D4: Added Filt | E4: Focal spot | F4: Tube voltage_x000D_(kV) | G4: Exposure time_x000D_(s) | H4: Exposure_x000D_(mGy) | I4: Exposure rate_x000D_(mGy/s) | J4: Total filtr._x000D_(mm Al) | K4: HVL_x000D_(mm Al) | L4: Exposure (norm)_x000D_(mGy) | M4: Exposure rate (norm)_x000D_(mGy/s)
A5: 50 | B5: 400 | C5: 10 | D5: 0 | E5: Large
A6: 60 | B6: 400 | C6: 20 | D6: 0 | E6: Large
A7: 70 | B7: 400 | C7: 10 | D7: 0 | E7: Large
A8: 80 | B8: 400 | C8: 20 | D8: 0 | E8: Large
A9: 80 | B9: 400 | C9: 20 | D9: 0 | E9: Large
A10: 80 | B10: 400 | C10: 20 | D10: 0 | E10: Large
A11: 80 | B11: 400 | C11: 20 | D11: 0 | E11: Large
A12: 80 | B12: 400 | C12: 20 | D12: 0 | E12: Large
A13: 80 | B13: 400 | C13: 20 | D13: 3 | E13: Large
A14: 80 | B14: 400 | C14: 20 | D14: 3 | E14: Large
A15: 80 | B15: 400 | C15: 20 | D15: 4 | E15: Large
A16: 80 | B16: 400 | C16: 20 | D16: 4 | E16: Large
... A28: 140 | B28: 400 | C28: 20 | D28: 0 | E28: Large

Sheet Lateral Gen
A1: Lateral tube
A2: Measurements
A4: Set kV_x000D_(kV) | B4: Set mA_x000D_(mA) | C4: Set mAs_x000D_(mAs) | D4: Added Filt | E4: Focal spot | F4: Tube voltage_x000D_(kV) | G4: Exposure time_x000D_(s) | H4: Exposure_x000D_(mGy) | I4: Exposure rate_x000D_(mGy/s) | J4: Total filtr._x000D_(mm Al) | K4: HVL_x000D_(mm Al) | L4: Exposure (norm)_x000D_(mGy) | M4: Exposure rate (norm)_x000D_(mGy/s)
A5: 50 | B5: 400 | C5: 10 | D5: 0 | E5: Large
A6: 60 | B6: 400 | C6: 20 | D6: 0 | E6: Large
A7: 70 | B7: 400 | C7: 10 | D7: 0 | E7: Large
A8: 80 | B8: 400 | C8: 20 | D8: 0 | E8: Large
A9: 80 | B9: 400 | C9: 20 | D9: 0 | E9: Large
A10: 80 | B10: 400 | C10: 20 | D10: 0 | E10: Large
A11: 80 | B11: 400 | C11: 20 | D11: 0 | E11: Large
A12: 80 | B12: 400 | C12: 20 | D12: 0 | E12: Large
A13: 80 | B13: 400 | C13: 20 | D13: 3 | E13: Large
A14: 80 | B14: 400 | C14: 20 | D14: 3 | E14: Large
A15: 80 | B15: 400 | C15: 20 | D15: 4 | E15: Large
A16: 80 | B16: 400 | C16: 20 | D16: 4 | E16: Large
... A28: 140 | B28: 400 | C28: 20 | D28: 0 | E28: Large

Sheet AEC
A1: Measurements
A3: Plane | B3: Thickness (cm) | C3: Set kV_x000D_(kV) | D3: Set mA_x000D_(mA) | E3: Exposure_x000D_(mGy) | F3: Exposure rate_x000D_(mGy/min) | G3: Exposure time_x000D_(ms)
A4: Frontal | B4: 10
A5: Frontal | B5: 20
A6: Frontal | B6: 20
A7: Frontal | B7: 20
A8: Frontal | B8: 30
A9: Lateral | B9: 10
A10: Lateral | B10: 20
A11: Lateral | B11: 20
A12: Lateral | B12: 20
A13: Lateral | B13: 30

Sheet DAP
A1: Measurements
A3: Plane | B3: Set kV_x000D_(kV) | C3: Set mA_x000D_(mA) | D3: Set time_x000D_(s) | E3: Set mAs_x000D_(mAs) | F3: KAP exposure_x000D_(µGym²) | G3: KAP exposure rate_x000D_(mGycm²/s) | H3: Indicated KAP | I3: KAP % diff
A4: Frontal | B4: 60 | C4: 100 | D4: 0.1 | E4: 10
A5: Frontal | B5: 80 | C5: 50 | D5: 0.2 | E5: 10
A6: Frontal | B6: 100 | C6: 50 | D6: 0.2 | E6: 10
A7: Frontal | B7: 120 | C7: 25 | D7: 0.4 | E7: 10
A8: Lateral | B8: 60 | C8: 100 | D8: 0.1 | E8: 10
A9: Lateral | B9: 80 | C9: 50 | D9: 0.2 | E9: 10
A10: Lateral | B10: 100 | C10: 50 | D10: 0.2 | E10: 10
A11: Lateral | B11: 120 | C11: 25 | D11: 0.4 | E11: 10

Sheet Tables
A1: RTI Piranha
A2: Piranha 1 | B2: Piranha 1 CB2-17090320
A3: Piranha 2 | B3: Piranha 2 CB2-19020491
A5: RTI DAP chamber
A6: DAP 1 | B6: DAP 1 2501554
A7: DAP 2 | B7: DAP 2 2501555
A9: KAP Conversion Table
B10: µGy·m²
A11: mGy·cm² | B11: 0.1
A12: cGy·cm² | B12: 1
A13: dGy·cm² | B13: 10
A14: Gy·cm² | B14: 100
A15: µGy·m² | B15: 1
A17: ESE Limits - Title B Part IV Appendix D
D18: Film speed | F18: Film speed
C19: Thickness | D19: 200/Dig | E19: 400 | F19: 200/Dig | G19: 400
A20: Projection | C20: (cm) | D20: mR | F20: mGy
A21: PA Chest - Grid | C21: 23 | D21: 38 | E21: 23 | F21: =D21*0.00876 -> 0.33288 | G21: =E21*0.00876 -> 0.20148
A22: PA Chest - Non grid | C22: 23 | D22: 23 | E22: 8 | F22: =D22*0.00876 -> 0.20148 | G22: =E22*0.00876 -> 0.07008
A23: AP Abdomen | C23: 23 | D23: 735 | E23: 450 | F23: =D23*0.00876 -> 6.4386 | G23: =E23*0.00876 -> 3.942
A24: AP Lumbar spine | C24: 23 | D24: 675 | E24: 525 | F24: =D24*0.00876 -> 5.913 | G24: =E24*0.00876 -> 4.599
A25: AP full spine | C25: 23 | D25: 390 | E25: 218 | F25: =D25*0.00876 -> 3.4164 | G25: =E25*0.00876 -> 1.90968
A26: AP C-spine | C26: 13 | D26: 203 | E26: 142 | F26: =D26*0.00876 -> 1.77828 | G26: =E26*0.00876 -> 1.24392
A27: Lateral skull | C27: 15 | D27: 218 | E27: 105 | F27: =D27*0.00876 -> 1.90968 | G27: =E27*0.00876 -> 0.9198
A28: AP Ret Pyelogram | C28: 23 | D28: 893 | E28: 893 | F28: =D28*0.00876 -> 7.82268 | G28: =E28*0.00876 -> 7.82268
A29: AP T-spine | C29: 23 | D29: 612 | E29: 612 | F29: =D29*0.00876 -> 5.36112 | G29: =E29*0.00876 -> 5.36112
A30: DP Foot | C30: 8 | D30: 111 | E30: 111 | F30: =D30*0.00876 -> 0.97236 | G30: =E30*0.00876 -> 0.97236
A31: Cephalometric | C31: 15 | D31: 45 | E31: 45 | F31: =D31*0.00876 -> 0.3942 | G31: =E31*0.00876 -> 0.3942
A33: RAD / DENTAL UNITS (SCDES CRITERIA)
B34: HVL
A35: kVp | B35: (mm Al)
A36: 30 | B36: 0.3
A37: 40 | B37: 0.4
A38: 50 | B38: 0.5
A39: 51 | B39: 1.3
A40: 60 | B40: 1.5
A41: 70 | B41: 1.8
A42: 71 | B42: 2.5
A43: 80 | B43: 2.9
A44: 90 | B44: 3.2
...
