Workbook
Name _RCTL: Gen_form!$AG$16
Name ALUM: Gen_form!$P$951:$P$952
Name ALUM_0: Gen_form!$M$951
Name ALUM_1: Gen_form!$M$952
Name ALUM_2: Gen_form!$M$953
Name ALUM_3: Gen_form!$M$954
Name ALUM_4: Gen_form!$M$955
Name ALUM_5: Gen_form!$M$956
Name ALUMHIGH: Gen_form!$P$952
Name ALUMLOW: Gen_form!$P$951
Name avgkvp: Gen_form!$Q$951
Name BeamLim: Gen_form!$M$404
Name BLD: Gen_form!$B$463:$K$528
Name COMPG2: Gen_form!$B$199:$K$264
Name COMPG3: Gen_form!$B$265:$K$330
Name COMPG4: Gen_form!$B$331:$K$396
Name DATA1: Gen_form!$B$1453:$K$1518
Name DATA2: Gen_form!$B$1519:$K$1716
Name DHALF: Gen_form!$O$951:$O$956
Name EXP: Gen_form!$B$397:$K$462
Name EXP_0: Gen_form!$N$951
Name EXP_1: Gen_form!$N$952
Name EXP_2: Gen_form!$N$953
Name EXP_3: Gen_form!$N$954
Name EXP_4: Gen_form!$N$955
Name EXP_5: Gen_form!$N$956
Name Exp_chart_1: "Chart 358"
Name Exp_chart_2: "Chart 359"
Name EXPHIGH: Gen_form!$P$956
Name EXPLOW: Gen_form!$P$955
Name FIRST: Gen_form!$B$1:$K$198
Name FS_KV: Gen_form!$B$661:$K$726
Name GENDATA: Gen_form!$Y$687:$BC$726
Name GenReturn: Gen_form!$L$686:$W$722
Name HALFVAL: Gen_form!$B$925:$K$990
Name HVL: Gen_form!$S$951
Name KAP_AK: Gen_form!$B$1189:$K$1254
Name LAST: Gen_form!$B$1387:$K$1452
Name LASTYEAR: Gen_form!$AB$8:$AB$558
Name LFMAS: Gen_form!$P$667
Name LFSDD: Gen_form!$N$693
Name LIN: Gen_form!$B$859:$K$924
Name LN_EXP: Gen_form!$Q$955:$Q$956
Name MASM: Gen_form!$I$1008:$I$1011
Name MASP: Gen_form!$I$1003:$I$1006
Name MAXAVG: Gen_form!$U$930
Name Meter_OD: Gen_form!$Q$999
Name METM: Gen_form!$G$1008:$G$1011
Name METP: Gen_form!$G$1003:$G$1006
Name PT_DEN: Gen_form!$B$991:$K$1056
Name PT_TB: Gen_form!$B$1057:$K$1122
Name PT_TB_CR: Gen_form!$B$1255:$K$1320
Name PT_WB: Gen_form!$B$1123:$K$1188
Name PT_WB_CR: Gen_form!$B$1321:$K$1386
Name Query_from_Compliance_Reports: Gen_form!$Z$748:$AK$768
Name RadSafe: Gen_form!$M$1426
Name REPRO: Gen_form!$B$727:$K$792
Name SFMAS: Gen_form!$P$672
Name SFSDD: Gen_form!$N$711
Name startend: Gen_form!$O$8

Sheet Gen_form
A1: 1 | M1: Revision 101.4.2-20260417 (Has 39 data records) | T1: =IF(OR(AB538="",AB538=0),"",AB538) | Y1: PRINT AREAS
A2: 2 | F2: Medical University of South Carolina | Q2: =$F$2 -> Medical University of South Carolina | T2: =IF(OR(AB539="",AB539=0),"",AB539) | Y2: FIRST,EXP,BLD,TB,WB,FS_KV,REPRO,TIM,LIN,HALFVAL,PT_DEN,PT_TB,PT_WB,KAP_AK,LAST
A3: 3 | F3: Charleston, South Carolina | Q3: =$F$3 -> Charleston, South Carolina | T3: =IF(OR(AB540="",AB540=0),"",AB540) | Y3: ALL: | Z3: FIRST,COMPG2,COMPG3,COMPG4,EXP,BLD,TB,WB,FS_KV,REPRO,TIM,LIN,HALFVAL,PT_DEN,PT_TB,PT_WB,KAP_AK,LAST,DATA1,DATA2
A4: 4 | T4: =IF(OR(AB541="",AB541=0),"",AB541) | AA4: REM: | AB4: (1) Go to last year's spreadsheet (see "**Note", below) and copy from ITS "THIS YEAR" range
A5: 5 | F5: Radiographic System Compliance Inspection | P5: =$F$5 -> Radiographic System Compliance Inspection | T5: =IF(OR(AB542="",AB542=0),"",AB542) | AB5: (2) Come back to this sheet and paste (use paste special, "values") into "LAST YEAR" range
A6: 6 | T6: =IF(OR(AB543="",AB543=0),"",AB543) | AB6: LAST | AC6: Cell AD6 | AD6: THIS
A7: 7 | AA7: Measurement Parameter | AB7: YEAR | AD7: YEAR | AE7: (Locked) | AF7: RANGES: | AG7: LASTYEAR (Data, starting with cell AB8)
A8: 8 | F8: System Information | N8: Date: | R8: =$F$8 -> System Information | U8: Inspector: | V8: Eugene Mah | AA8: Print Area: | AC8: =IF(AND(OR(AB8="",AB8=0),OR(AD8="",AD8=0)),"",IF(AB8<>AD8,"Change","")) -> Change | AD8: =IF(Y2="","",Y2) -> FIRST,EXP,BLD,TB,WB,FS_KV,REPRO,TIM,LIN,HALFVAL,PT_DEN,PT_TB,PT_WB,KAP_AK,LAST | AE8: Y2 | AG8: THISYEAR (Data, starting with cell AD8)
A9: 9 | N9: Last Year: | O9: =IF(OR(AB9=0,AB9=""),"",AB9) | U9: Last Year: | V9: =IF(OR(AB10=0,AB10=""),"",AB10) | AA9: Date: | AC9: =IF(AND(OR(AB9="",AB9=0),OR(AD9="",AD9=0)),"",IF(AB9<>AD9,"Change","")) | AD9: =IF(O8="","",O8) | AE9: O8
A10: 10 | C10: Location | N10: Location | Q10: Input Changes Only | U10: Input Changes Only | AA10: Inspector: | AC10: =IF(AND(OR(AB10="",AB10=0),OR(AD10="",AD10=0)),"",IF(AB10<>AD10,"Change","")) -> Change | AD10: =IF(V8="","",V8) -> Eugene Mah | AE10: V8
A11: 11 | D11: Facility: | E11: =IF(P11="","",P11) | H11: Site: | I11: =IF(T11="","",T11) | O11: Facility: | P11: =IF(Q11<>"",Q11,IF(OR(AB11=0,AB11=""),"",AB11)) | S11: Site Number: | T11: =IF(U11<>"",U11,IF(OR(AB48=0,AB48=""),"",AB48)) | AA11: =IF(O11="","",O11) -> Facility: | AC11: =IF(AND(OR(AB11="",AB11=0),OR(AD11="",AD11=0)),"",IF(AB11<>AD11,"Change","")) | AD11: =IF(P11="","",P11) | AE11: P11
A12: 12 | D12: Department: | E12: =IF(P12="","",P12) | H12: Authorized Use: | I12: =IF(T12="","",T12) | O12: Department: | P12: =IF(Q12<>"",Q12,IF(OR(AB12=0,AB12=""),"",AB12)) | S12: Authorized Use: | T12: =IF(U12<>"",U12,IF(OR(AB49=0,AB49=""),"",AB49)) | AA12: =IF(O12="","",O12) -> Department: | AC12: =IF(AND(OR(AB12="",AB12=0),OR(AD12="",AD12=0)),"",IF(AB12<>AD12,"Change","")) | AD12: =IF(P12="","",P12) | AE12: P12
A13: 13 | D13: Area/Division: | E13: =IF(P13="","",P13) | H13: Date of Installation: | I13: =IF(T13="","",T13) | O13: Area/Division: | P13: =IF(Q13<>"",Q13,IF(OR(AB13=0,AB13=""),"",AB13)) | S13: Date of Installation: | T13: =IF(U13<>"",U13,IF(OR(AB50=0,AB50=""),"",AB50)) | AA13: =IF(O13="","",O13) -> Area/Division: | AC13: =IF(AND(OR(AB13="",AB13=0),OR(AD13="",AD13=0)),"",IF(AB13<>AD13,"Change","")) | AD13: =IF(P13="","",P13) | AE13: P13
A14: 14 | D14: Survey ID: | E14: =IF(P14="","",P14) | H14: Number of X-ray Tubes: | I14: =IF(T14="","",T14) | O14: Survey ID: | P14: =IF(Q14<>"",Q14,IF(OR(AB14=0,AB14=""),"",AB14)) | S14: Number of X-ray Tubes: | T14: =IF(U14<>"",U14,IF(OR(AB51=0,AB51=""),"",AB51)) | AA14: =IF(O14="","",O14) -> Survey ID: | AC14: =IF(AND(OR(AB14="",AB14=0),OR(AD14="",AD14=0)),"",IF(AB14<>AD14,"Change","")) | AD14: =IF(P14="","",P14) | AE14: P14
A15: 15 | O15: Room Number: | P15: =IF(Q15<>"",Q15,IF(OR(AB15=0,AB15=""),"",AB15)) | S15: Accession Number: | T15: =IF(U15<>"",U15,IF(OR(AB52=0,AB52=""),"",AB52)) | AA15: =IF(O15="","",O15) -> Room Number: | AC15: =IF(AND(OR(AB15="",AB15=0),OR(AD15="",AD15=0)),"",IF(AB15<>AD15,"Change","")) | AD15: =IF(P15="","",P15) | AE15: P15
A16: 16 | AA16: =IF(O16="","",O16) | AC16: =IF(AND(OR(AB16="",AB16=0),OR(AD16="",AD16=0)),"",IF(AB16<>AD16,"Change",""))
A17: 17 | C17: X-Ray Generator | N17: X-Ray Generator | AA17: X-Ray Generator | AC17: =IF(AND(OR(AB17="",AB17=0),OR(AD17="",AD17=0)),"",IF(AB17<>AD17,"Change",""))
A18: 18 | D18: Manufacturer: | E18: =IF(P18="","",P18) | H18: Date of Manufacture: | I18: =IF(T18="","",T18) | O18: Manufacturer: | P18: =IF(Q18<>"",Q18,IF(OR(AB18=0,AB18=""),"",AB18)) | S18: Date of Manufacture: | T18: =IF(U18<>"",U18,IF(OR(AB54=0,AB54=""),"",AB54)) | AA18: =IF(O18="","",O18) -> Manufacturer: | AC18: =IF(AND(OR(AB18="",AB18=0),OR(AD18="",AD18=0)),"",IF(AB18<>AD18,"Change","")) | AD18: =IF(P18="","",P18) | AE18: P18
A19: 19 | D19: Model: | E19: =IF(P19="","",P19) | H19: Serial Number: | I19: =IF(T19="","",T19) | O19: Model: | P19: =IF(Q19<>"",Q19,IF(OR(AB19=0,AB19=""),"",AB19)) | S19: Serial Number: | T19: =IF(U19<>"",U19,IF(OR(AB55=0,AB55=""),"",AB55)) | AA19: =IF(O19="","",O19) -> Model: | AC19: =IF(AND(OR(AB19="",AB19=0),OR(AD19="",AD19=0)),"",IF(AB19<>AD19,"Change","")) | AD19: =IF(P19="","",P19) | AE19: P19
A20: 20 | D20: Max. kVp: | E20: =IF(P20="","",P20) | H20: Max. mA: | I20: =IF(T20="","",T20) | O20: Max. kVp: | P20: =IF(Q20<>"",Q20,IF(OR(AB20=0,AB20=""),"",AB20)) | S20: Max. mA: | T20: =IF(U20<>"",U20,IF(OR(AB56=0,AB56=""),"",AB56)) | AA20: =IF(O20="","",O20) -> Max. kVp: | AC20: =IF(AND(OR(AB20="",AB20=0),OR(AD20="",AD20=0)),"",IF(AB20<>AD20,"Change","")) | AD20: =IF(P20="","",P20) | AE20: P20
A21: 21 | D21: Software Version: | E21: =IF(P21="","",P21) | O21: Software Version: | P21: =IF(Q21<>"",Q21,IF(OR(AB21=0,AB21=""),"",AB21)) | AA21: =IF(O21="","",O21) -> Software Version: | AC21: =IF(AND(OR(AB21="",AB21=0),OR(AD21="",AD21=0)),"",IF(AB21<>AD21,"Change","")) | AD21: =IF(P21="","",P21)
A22: 22 | AA22: =IF(O22="","",O22) | AC22: =IF(AND(OR(AB22="",AB22=0),OR(AD22="",AD22=0)),"",IF(AB22<>AD22,"Change",""))
A23: 23 | C23: =IF(N23="","",N23) -> X-Ray Tube 1 | I23: Focal Spot Sizes | N23: X-Ray Tube 1 | T23: Focal Spot Sizes (mm) | AA23: X-Ray Tube 1 | AC23: =IF(AND(OR(AB23="",AB23=0),OR(AD23="",AD23=0)),"",IF(AB23<>AD23,"Change",""))
A24: 24 | D24: Tube Designation/Use: | E24: =IF(P24="","",P24) | H24: =IF(S24="","",S24) -> Large: | I24: =IF(T24="","",T24) | O24: Tube Designation/Use: | P24: =IF(Q24<>"",Q24,IF(OR(AB24=0,AB24=""),"",AB24)) | S24: Large: | T24: =IF(U24<>"",U24,IF(OR(AB59=0,AB59=""),"",AB59)) | AA24: =IF(O24="","",O24) -> Tube Designation/Use: | AC24: =IF(AND(OR(AB24="",AB24=0),OR(AD24="",AD24=0)),"",IF(AB24<>AD24,"Change","")) | AD24: =IF(P24="","",P24) | AE24: P24
A25: 25 | D25: Date of Manufacture: | E25: =IF(P25="","",P25) | H25: =IF(S25="","",S25) -> Small: | I25: =IF(T25="","",T25) | O25: Date of Manufacture: | P25: =IF(Q25<>"",Q25,IF(OR(AB25=0,AB25=""),"",AB25)) | S25: Small: | T25: =IF(U25<>"",U25,IF(OR(AB60=0,AB60=""),"",AB60)) | AA25: =IF(O25="","",O25) -> Date of Manufacture: | AC25: =IF(AND(OR(AB25="",AB25=0),OR(AD25="",AD25=0)),"",IF(AB25<>AD25,"Change","")) | AD25: =IF(P25="","",P25) | AE25: P25
A26: 26 | H26: =IF(T26="","",S26) | I26: =IF(T26="","",T26) | S26: Micro: | T26: =IF(U26<>"",U26,IF(OR(AB61=0,AB61=""),"",AB61)) | AA26: =IF(O26="","",O26) | AC26: =IF(AND(OR(AB26="",AB26=0),OR(AD26="",AD26=0)),"",IF(AB26<>AD26,"Change",""))
A27: 27 | D27: Insert Manufacturer: | E27: =IF(P27="","",P27) | I27: Filtration | O27: Insert Manufacturer: | P27: =IF(Q27<>"",Q27,IF(OR(AB27=0,AB27=""),"",AB27)) | T27: Filtration | AA27: =IF(O27="","",O27) -> Insert Manufacturer: | AC27: =IF(AND(OR(AB27="",AB27=0),OR(AD27="",AD27=0)),"",IF(AB27<>AD27,"Change","")) | AD27: =IF(P27="","",P27) | AE27: P27
A28: 28 | D28: Insert Model: | E28: =IF(P28="","",P28) | H28: Inherent: | I28: =IF(T28="","",T28) | O28: Insert Model: | P28: =IF(Q28<>"",Q28,IF(OR(AB28=0,AB28=""),"",AB28)) | S28: Inherent: | T28: =IF(U28<>"",U28,IF(OR(AB63=0,AB63=""),"",AB63)) | AA28: =IF(O28="","",O28) -> Insert Model: | AC28: =IF(AND(OR(AB28="",AB28=0),OR(AD28="",AD28=0)),"",IF(AB28<>AD28,"Change","")) | AD28: =IF(P28="","",P28) | AE28: P28
A29: 29 | D29: Insert Serial Number: | E29: =IF(P29="","",P29) | H29: Added: | I29: =IF(T29="","",T29) | O29: Insert Serial Number: | P29: =IF(Q29<>"",Q29,IF(OR(AB29=0,AB29=""),"",AB29)) | S29: Added: | T29: =IF(U29<>"",U29,IF(OR(AB64=0,AB64=""),"",AB64)) | AA29: =IF(O29="","",O29) -> Insert Serial Number: | AC29: =IF(AND(OR(AB29="",AB29=0),OR(AD29="",AD29=0)),"",IF(AB29<>AD29,"Change","")) | AD29: =IF(P29="","",P29) | AE29: P29
A30: 30 | AA30: =IF(O30="","",O30) | AC30: =IF(AND(OR(AB30="",AB30=0),OR(AD30="",AD30=0)),"",IF(AB30<>AD30,"Change",""))
A31: 31 | D31: Housing Manufacturer: | E31: =IF(P31="","",P31) | I31: Image Receptor | O31: Housing Manufacturer: | P31: =IF(Q31<>"",Q31,IF(OR(AB31=0,AB31=""),"",AB31)) | T31: Image Receptor | AA31: =IF(O31="","",O31) -> Housing Manufacturer: | AC31: =IF(AND(OR(AB31="",AB31=0),OR(AD31="",AD31=0)),"",IF(AB31<>AD31,"Change","")) | AD31: =IF(P31="","",P31) | AE31: P31
A32: 32 | D32: Housing Model: | E32: =IF(P32="","",P32) | H32: Film: | I32: =IF(T32="","",T32) | O32: Housing Model: | P32: =IF(Q32<>"",Q32,IF(OR(AB32=0,AB32=""),"",AB32)) | S32: Film: | T32: =IF(U32<>"",U32,IF(OR(AB67=0,AB67=""),"",AB67)) | AA32: =IF(O32="","",O32) -> Housing Model: | AC32: =IF(AND(OR(AB32="",AB32=0),OR(AD32="",AD32=0)),"",IF(AB32<>AD32,"Change","")) | AD32: =IF(P32="","",P32) | AE32: P32
A33: 33 | D33: Housing Serial Number: | E33: =IF(P33="","",P33) | H33: Screen: | I33: =IF(T33="","",T33) | O33: Housing Serial Number: | P33: =IF(Q33<>"",Q33,IF(OR(AB33=0,AB33=""),"",AB33)) | S33: Screen: | T33: =IF(U33<>"",U33,IF(OR(AB68=0,AB68=""),"",AB68)) | AA33: =IF(O33="","",O33) -> Housing Serial Number: | AC33: =IF(AND(OR(AB33="",AB33=0),OR(AD33="",AD33=0)),"",IF(AB33<>AD33,"Change","")) | AD33: =IF(P33="","",P33) | AE33: P33
A34: 34 | AA34: =IF(O34="","",O34) | AC34: =IF(AND(OR(AB34="",AB34=0),OR(AD34="",AD34=0)),"",IF(AB34<>AD34,"Change",""))
A35: 35 | AA35: =IF(O35="","",O35) | AC35: =IF(AND(OR(AB35="",AB35=0),OR(AD35="",AD35=0)),"",IF(AB35<>AD35,"Change",""))
A36: 36 | C36: =IF(N36="","",N36) -> X-Ray Tube 2 | I36: Focal Spot Sizes | N36: X-Ray Tube 2 | T36: Focal Spot Sizes (mm) | AA36: X-Ray Tube 2 | AC36: =IF(AND(OR(AB36="",AB36=0),OR(AD36="",AD36=0)),"",IF(AB36<>AD36,"Change",""))
A37: 37 | D37: Tube Designation/Use: | E37: =IF(P37="","",P37) | H37: =IF(S37="","",S37) -> Large: | I37: =IF(T37="","",T37) | O37: Tube Designation/Use: | P37: =IF(Q37<>"",Q37,IF(OR(AB37=0,AB37=""),"",AB37)) | S37: Large: | T37: =IF(U37<>"",U37,IF(OR(AB71=0,AB71=""),"",AB71)) | AA37: =IF(O37="","",O37) -> Tube Designation/Use: | AC37: =IF(AND(OR(AB37="",AB37=0),OR(AD37="",AD37=0)),"",IF(AB37<>AD37,"Change","")) | AD37: =IF(P37="","",P37) | AE37: P37
A38: 38 | D38: Date of Manufacture: | E38: =IF(P38="","",P38) | H38: =IF(S38="","",S38) -> Small: | I38: =IF(T38="","",T38) | O38: Date of Manufacture: | P38: =IF(Q38<>"",Q38,IF(OR(AB38=0,AB38=""),"",AB38)) | S38: Small: | T38: =IF(U38<>"",U38,IF(OR(AB72=0,AB72=""),"",AB72)) | AA38: =IF(O38="","",O38) -> Date of Manufacture: | AC38: =IF(AND(OR(AB38="",AB38=0),OR(AD38="",AD38=0)),"",IF(AB38<>AD38,"Change","")) | AD38: =IF(P38="","",P38) | AE38: P38
A39: 39 | H39: =IF(T39="","",S39) | I39: =IF(T39="","",T39) | J39: =IF(T39="","",U39) | S39: Micro: | T39: =IF(U39<>"",U39,IF(OR(AB73=0,AB73=""),"",AB73)) | AA39: =IF(O39="","",O39) | AC39: =IF(AND(OR(AB39="",AB39=0),OR(AD39="",AD39=0)),"",IF(AB39<>AD39,"Change",""))
A40: 40 | D40: Insert Manufacturer: | E40: =IF(P40="","",P40) | I40: Filtration | O40: Insert Manufacturer: | P40: =IF(Q40<>"",Q40,IF(OR(AB40=0,AB40=""),"",AB40)) | T40: Filtration | AA40: =IF(O40="","",O40) -> Insert Manufacturer: | AC40: =IF(AND(OR(AB40="",AB40=0),OR(AD40="",AD40=0)),"",IF(AB40<>AD40,"Change","")) | AD40: =IF(P40="","",P40) | AE40: P40
...

Sheet Tables
A1: RTI Piranha
A2: Piranha 1 | B2: Piranha 1 CB2-17090320
A3: Piranha 2 | B3: Piranha 2 CB2-19020491
A5: RTI DAP chamber
A6: DAP 1 | B6: DAP 1 2501554
A7: DAP 2 | B7: DAP 2 2501555
A9: KAP Conversion Table
B10: µGy·m²
A11: mGy·cm² | B11: 0.1
A12: cGy·cm² | B12: 1
A13: dGy·cm² | B13: 10
A14: Gy·cm² | B14: 100
A15: µGy·m² | B15: 1

Sheet Sheet1
A1: Measurements | P1: Measurements | R1: Measurements
A3: Set kV_x000D_(kV) | B3: Set mA_x000D_(mA) | C3: Set mAs_x000D_(mAs) | D3: Set time_x000D_(s) | E3: Added Filt | F3: Focal spot | G3: Tube voltage_x000D_(kV) | H3: Exposure time_x000D_(s) | I3: Exposure_x000D_(mGy) | J3: Exposure rate_x000D_(mGy/s) | K3: Total filtr._x000D_(mm Al) | L3: HVL_x000D_(mm Al) | M3: Exposure (norm)_x000D_(mGy) | N3: Exposure rate (norm)_x000D_(mGy/s) | P3: Light_x000D_(lx) | R3: Set kV_x000D_(kV) | S3: Set mA_x000D_(mA) | T3: Set time_x000D_(s) | U3: Set mAs_x000D_(mAs) | V3: KAP exposure_x000D_(µGym²) | W3: KAP exposure rate_x000D_(mGycm²/s) | X3: Indicated KAP | Y3: KAP % diff
A4: 60 | B4: 400 | C4: 20 | D4: 0.05 | E4: 0 | F4: Large | R4: 60 | S4: 100 | T4: 0.1 | U4: 10
A5: 80 | B5: 400 | C5: 20 | D5: 0.05 | E5: 0 | F5: Large | R5: 80 | S5: 50 | T5: 0.2 | U5: 10
A6: 80 | B6: 400 | C6: 20 | D6: 0.05 | E6: 0 | F6: Large | R6: 100 | S6: 50 | T6: 0.2 | U6: 10
A7: 80 | B7: 400 | C7: 20 | D7: 0.05 | E7: 0 | F7: Large | R7: 120 | S7: 25 | T7: 0.4 | U7: 10
A8: 80 | B8: 400 | C8: 20 | D8: 0.05 | E8: 0 | F8: Large
A9: 80 | B9: 400 | C9: 20 | D9: 0.05 | E9: 0 | F9: Large
A10: 80 | B10: 400 | C10: 20 | D10: 0.05 | E10: 3 | F10: Large
A11: 80 | B11: 400 | C11: 20 | D11: 0.05 | E11: 3 | F11: Large
A12: 80 | B12: 400 | C12: 20 | D12: 0.05 | E12: 3.5 | F12: Large
A13: 80 | B13: 400 | C13: 20 | D13: 0.05 | E13: 3.5 | F13: Large
A14: 80 | B14: 400 | C14: 20 | D14: 0.05 | E14: 2.5 | F14: Large
A15: 80 | B15: 400 | C15: 20 | D15: 0.05 | E15: 2.5 | F15: Large
A16: 80 | B16: 500 | C16: 25 | D16: 0.05 | E16: 0 | F16: Large
A17: 80 | B17: 50 | C17: 2.5 | D17: 0.05 | E17: 0 | F17: Large
A18: 80 | B18: 800 | C18: 40 | D18: 0.05 | E18: 0 | F18: Large
A19: 80 | B19: 250 | C19: 12.5 | D19: 0.05 | E19: 0 | F19: Large
... A42: 80 | B42: 200 | C42: 80 | D42: 0.4 | E42: 0 | F42: Large

Sheet DataPage
A1: Sheet | B1: RAD
A2: SurveyID | B2: =Gen_form!E14
A3: SID | B3: =Gen_form!S484
A4: Illumination | B4: =Gen_form!U504 -> TBD
A5: Beam Align | B5: =Gen_form!R537 -> TBD
A6: Rad/film center table | B6: =Gen_form!Q547 -> 0
A7: Rad/film center wall | B7: =Gen_form!Q608 -> 0
A8: LFS | B8: =Gen_form!U669 -> 0
A9: SFS | B9: =Gen_form!U674 -> 0
A10: Table SID | B10: =Gen_form!K543
A11: Wall SID | B11: =Gen_form!C615
A12: Collimation table | B12: =Gen_form!B554 | C12: =Gen_form!C554 | D12: =Gen_form!D554 | E12: =Gen_form!E554 | F12: =Gen_form!F554 | G12: =Gen_form!G554
B13: =Gen_form!B555 | C13: =Gen_form!C555 | D13: =Gen_form!D555 | E13: =Gen_form!E555 | F13: =Gen_form!F555 | G13: =Gen_form!G555
A14: PBL table | B14: =Gen_form!B575 -> NA | C14: =Gen_form!C575 -> NA
B15: =Gen_form!B576 -> NA | C15: =Gen_form!C576 -> NA
A16: Collimation wall | B16: =Gen_form!D615 | C16: =Gen_form!E615 | D16: =Gen_form!F615 | E16: =Gen_form!G615 | F16: =Gen_form!H615 -> 14 | G16: =Gen_form!I615 -> 18
B17: =Gen_form!D616 | C17: =Gen_form!E616 | D17: =Gen_form!F616 | E17: =Gen_form!G616 | F17: =Gen_form!H616 | G17: =Gen_form!I616
A18: PBL wall | B18: =Gen_form!C637 -> NA | C18: =Gen_form!D637 -> NA
B19: =Gen_form!C638 -> NA | C19: =Gen_form!D638 -> NA
A20: LFS Output | B20: =Gen_form!D1394 | C20: =Gen_form!E1394
B21: =Gen_form!D1395 | C21: =Gen_form!E1395
B22: =Gen_form!D1396 | C22: =Gen_form!E1396
B23: =Gen_form!D1397 | C23: =Gen_form!E1397
B24: =Gen_form!D1398 | C24: =Gen_form!E1398
B25: =Gen_form!D1399 | C25: =Gen_form!E1399
B26: =Gen_form!D1400 | C26: =Gen_form!E1400
B27: =Gen_form!D1401 | C27: =Gen_form!E1401
A28: SFS Output | B28: =Gen_form!D1407 | C28: =Gen_form!E1407
B29: =Gen_form!D1408 | C29: =Gen_form!E1408
B30: =Gen_form!D1409 | C30: =Gen_form!E1409
B31: =Gen_form!D1410 | C31: =Gen_form!E1410
B32: =Gen_form!D1411 | C32: =Gen_form!E1411
B33: =Gen_form!D1412 | C33: =Gen_form!E1412
A34: Gen Test | B34: =Gen_form!AA688 -> 0 | C34: =Gen_form!AB688 -> 0 | D34: =Gen_form!AC688 -> 0 | E34: =Gen_form!AD688 -> 0 | F34: =Gen_form!AE688 -> 0 | G34: =Gen_form!AF688 -> 0 | H34: =Gen_form!AG688 -> 0 | I34: =Gen_form!AH688 -> 0 | ... AC34: =Gen_form!BB688 -> 0
B35: =Gen_form!AA689 -> 0 | C35: =Gen_form!AB689 -> 0 | D35: =Gen_form!AC689 -> 0 | E35: =Gen_form!AD689 -> 0 | F35: =Gen_form!AE689 -> 0 | G35: =Gen_form!AF689 -> 0 | H35: =Gen_form!AG689 -> 0 | I35: =Gen_form!AH689 -> 0 | ... AC35: =Gen_form!BB689 -> 0
B36: =Gen_form!#REF! -> #REF! | C36: =Gen_form!#REF! -> #REF! | D36: =Gen_form!#REF! -> #REF! | E36: =Gen_form!#REF! -> #REF! | F36: =Gen_form!#REF! -> #REF! | G36: =Gen_form!#REF! -> #REF! | H36: =Gen_form!#REF! -> #REF! | I36: =Gen_form!#REF! -> #REF! | ... AC36: =Gen_form!#REF! -> #REF!
B37: =Gen_form!#REF! -> #REF! | C37: =Gen_form!#REF! -> #REF! | D37: =Gen_form!#REF! -> #REF! | E37: =Gen_form!#REF! -> #REF! | F37: =Gen_form!#REF! -> #REF! | G37: =Gen_form!#REF! -> #REF! | H37: =Gen_form!#REF! -> #REF! | I37: =Gen_form!#REF! -> #REF! | ... AC37: =Gen_form!#REF! -> #REF!
B38: =Gen_form!#REF! -> #REF! | C38: =Gen_form!#REF! -> #REF! | D38: =Gen_form!#REF! -> #REF! | E38: =Gen_form!#REF! -> #REF! | F38: =Gen_form!#REF! -> #REF! | G38: =Gen_form!#REF! -> #REF! | H38: =Gen_form!#REF! -> #REF! | I38: =Gen_form!#REF! -> #REF! | ... AC38: =Gen_form!#REF! -> #REF!
B39: =Gen_form!#REF! -> #REF! | C39: =Gen_form!#REF! -> #REF! | D39: =Gen_form!#REF! -> #REF! | E39: =Gen_form!#REF! -> #REF! | F39: =Gen_form!#REF! -> #REF! | G39: =Gen_form!#REF! -> #REF! | H39: =Gen_form!#REF! -> #REF! | I39: =Gen_form!#REF! -> #REF! | ... AC39: =Gen_form!#REF! -> #REF!
B40: =Gen_form!#REF! -> #REF! | C40: =Gen_form!#REF! -> #REF! | D40: =Gen_form!#REF! -> #REF! | E40: =Gen_form!#REF! -> #REF! | F40: =Gen_form!#REF! -> #REF! | G40: =Gen_form!#REF! -> #REF! | H40: =Gen_form!#REF! -> #REF! | I40: =Gen_form!#REF! -> #REF! | ... AC40: =Gen_form!#REF! -> #REF!
...
